Workbook

Sheet Daily KPI Entry
A1: STL FU — WEAVING | DAILY KPI DATA ENTRY
A3: ENTRY RULE: one row = one operator + one date + one actual shift + one loom. Existing grouped rows are preserved; use one loom per new row.
A4: White cells = user input. Blue cells = automatic. Running-hour target is 8 hours per designated loom per shift.
A5: Record No | B5: Date | C5: Planned Shift | D5: Actual Shift | E5: Shift Status | F5: Shift Change Reason | G5: Operator ID | H5: Operator Name | I5: Supervisor | J5: No. of Looms | K5: Loom No(s) | L5: Avg RPM | M5: Avg PPI | N5: Production Target (yd) | O5: Production Actual (yd) | P5: Production Achievement % | Q5: Running Hr Target / Loom | R5: Total Loom-Hr Target | S5: Running Hr Actual | T5: Running Achievement % | U5: Loom Efficiency % | V5: Rejection Yds | W5: Rejection % | X5: Warp Break | Y5: Weft Break | Z5: Missing Pick | AA5: Stop Mark | AB5: Start Mark | AC5: L. End | AD5: Y. Mix | AE5: Other Fault | AF5: Fault Total | AG5: Faults / 1000 yd | AH5: Housekeeping % | AI5: Attendance / Discipline % | AJ5: SOP / Safety % | AK5: Supervisor Remarks | AL5: Operator Comments | AM5: Verified
A6: 1 | B6: 46288 | C6: A | D6: A | E6: Normal | G6: STL005494 | H6: =IFERROR(INDEX('Operator Master'!$B$5:$B$504,MATCH(G6,'Operator Master'!$A$5:$A$504,0)),"") -> MD. MAHABUB ALAM | J6: 8 | K6: O4,O5,O6,P4,P5,Q4,Q5,Q6 | L6: 531.25 | M6: 42 | N6: 1500 | O6: 1130 | P6: =IF(OR(N6="",O6=""),"",IFERROR(O6/N6*100,0)) -> 75.333333 | Q6: 8 | R6: =IF(J6="","",Q6*J6) -> 64 | S6: 61 | T6: =IF(OR(R6="",S6=""),"",IFERROR(S6/R6*100,0)) -> 95.3125 | U6: =IF(OR(O6="",L6="",M6="",S6="",M6=0),"",IFERROR(O6/(L6*60*S6/(M6*36))*100,0)) -> 87.871938 | V6: 32 | W6: =IF(O6="","",IFERROR(V6/O6*100,0)) -> 2.8318584 | X6: 3 | Y6: 5 | Z6: 3 | AA6: 5 | AB6: 3 | AC6: 0 | AD6: 0 | AF6: =IF(O6="","",SUM(X6:AE6)) -> 19 | AG6: =IF(O6="","",IFERROR(AF6/O6*1000,0)) -> 16.814159 | AH6: 80 | AI6: 100 | AJ6: 90
A7: 2 | B7: 46288 | C7: B | D7: A | E7: Replace | F7: Manpower shortage | G7: STL005476 | H7: =IFERROR(INDEX('Operator Master'!$B$5:$B$504,MATCH(G7,'Operator Master'!$A$5:$A$504,0)),"") -> MD. RIPU MIAH | J7: 9 | K7: G6,G7,H5,H6,H7,I6,I7,J6,J7 | L7: 569.44444 | M7: 43.11 | N7: 1800 | O7: 1127 | P7: =IF(OR(N7="",O7=""),"",IFERROR(O7/N7*100,0)) -> 62.611111 | Q7: 8 | R7: =IF(J7="","",Q7*J7) -> 72 | S7: 68 | T7: =IF(OR(R7="",S7=""),"",IFERROR(S7/R7*100,0)) -> 94.444444 | U7: =IF(OR(O7="",L7="",M7="",S7="",M7=0),"",IFERROR(O7/(L7*60*S7/(M7*36))*100,0)) -> 75.282306 | V7: 17 | W7: =IF(O7="","",IFERROR(V7/O7*100,0)) -> 1.5084295 | X7: 6 | Y7: 4 | Z7: 7 | AA7: 3 | AB7: 6 | AC7: 1 | AD7: 0 | AF7: =IF(O7="","",SUM(X7:AE7)) -> 27 | AG7: =IF(O7="","",IFERROR(AF7/O7*1000,0)) -> 23.957409 | AH7: 90 | AI7: 95 | AJ7: 100
A8: 3 | B8: 46288 | C8: A | D8: A | E8: Normal | G8: STL005492 | H8: =IFERROR(INDEX('Operator Master'!$B$5:$B$504,MATCH(G8,'Operator Master'!$A$5:$A$504,0)),"") -> MD. MINHAZ ALI | J8: 10 | K8: K1,K2,K3,K4,K5,L1,L2,L3,L4,L5 | L8: 537.5 | M8: 41.6 | N8: 1900 | O8: 1602 | P8: =IF(OR(N8="",O8=""),"",IFERROR(O8/N8*100,0)) -> 84.315789 | Q8: 8 | R8: =IF(J8="","",Q8*J8) -> 80 | S8: 79 | T8: =IF(OR(R8="",S8=""),"",IFERROR(S8/R8*100,0)) -> 98.75 | U8: =IF(OR(O8="",L8="",M8="",S8="",M8=0),"",IFERROR(O8/(L8*60*S8/(M8*36))*100,0)) -> 94.167607 | V8: 20 | W8: =IF(O8="","",IFERROR(V8/O8*100,0)) -> 1.2484395 | X8: 4 | Y8: 4 | Z8: 1 | AA8: 3 | AB8: 2 | AC8: 0 | AD8: 0 | AF8: =IF(O8="","",SUM(X8:AE8)) -> 14 | AG8: =IF(O8="","",IFERROR(AF8/O8*1000,0)) -> 8.7390762 | AH8: 95 | AI8: 100 | AJ8: 100
A9: 4 | B9: 46288 | C9: A | D9: A | E9: Normal | G9: STL005502 | H9: =IFERROR(INDEX('Operator Master'!$B$5:$B$504,MATCH(G9,'Operator Master'!$A$5:$A$504,0)),"") -> MD. FORIDUL ISLAM | J9: 9 | K9: G1,G2,G3,G4,G5,H1,H2,H3,H4 | L9: 519.44444 | M9: 44.78 | N9: 1500 | O9: 781 | P9: =IF(OR(N9="",O9=""),"",IFERROR(O9/N9*100,0)) -> 52.066667 | Q9: 8 | R9: =IF(J9="","",Q9*J9) -> 72 | S9: 60 | T9: =IF(OR(R9="",S9=""),"",IFERROR(S9/R9*100,0)) -> 83.333333 | U9: =IF(OR(O9="",L9="",M9="",S9="",M9=0),"",IFERROR(O9/(L9*60*S9/(M9*36))*100,0)) -> 67.328047 | V9: 16 | W9: =IF(O9="","",IFERROR(V9/O9*100,0)) -> 2.0486556 | X9: 2 | Y9: 5 | Z9: 3 | AA9: 6 | AB9: 2 | AC9: 3 | AD9: 0 | AF9: =IF(O9="","",SUM(X9:AE9)) -> 21 | AG9: =IF(O9="","",IFERROR(AF9/O9*1000,0)) -> 26.888604 | AH9: 90 | AI9: 100 | AJ9: 100
A10: 5 | B10: 46288 | G10: STL005507 | H10: =IFERROR(INDEX('Operator Master'!$B$5:$B$504,MATCH(G10,'Operator Master'!$A$5:$A$504,0)),"") -> MD. SAIFUL ISLAM-2 | J10: 10 | K10: I1,I2,I3,I4,I5,J1,J2,J3,J4,J5 | L10: 582.5 | M10: 43.7 | N10: 1900 | O10: 1170 | P10: =IF(OR(N10="",O10=""),"",IFERROR(O10/N10*100,0)) -> 61.578947 | Q10: 8 | R10: =IF(J10="","",Q10*J10) -> 80 | S10: 78 | T10: =IF(OR(R10="",S10=""),"",IFERROR(S10/R10*100,0)) -> 97.5 | U10: =IF(OR(O10="",L10="",M10="",S10="",M10=0),"",IFERROR(O10/(L10*60*S10/(M10*36))*100,0)) -> 67.519313 | V10: 12 | W10: =IF(O10="","",IFERROR(V10/O10*100,0)) -> 1.025641 | X10: 5 | Y10: 3 | Z10: 4 | AA10: 1 | AB10: 5 | AC10: 1 | AD10: 1 | AF10: =IF(O10="","",SUM(X10:AE10)) -> 20 | AG10: =IF(O10="","",IFERROR(AF10/O10*1000,0)) -> 17.094017 | AH10: 95 | AI10: 100 | AJ10: 95
A11: 6 | B11: 46288 | G11: STL005510 | H11: =IFERROR(INDEX('Operator Master'!$B$5:$B$504,MATCH(G11,'Operator Master'!$A$5:$A$504,0)),"") -> MD. ZIAUL HAQUE | J11: 9 | K11: R3,R4,R5,R6,S4,S5,T4,T5,T6 | L11: 558.33333 | M11: 41.22 | N11: 1800 | O11: 1598 | P11: =IF(OR(N11="",O11=""),"",IFERROR(O11/N11*100,0)) -> 88.777778 | Q11: 8 | R11: =IF(J11="","",Q11*J11) -> 72 | S11: 68 | T11: =IF(OR(R11="",S11=""),"",IFERROR(S11/R11*100,0)) -> 94.444444 | U11: =IF(OR(O11="",L11="",M11="",S11="",M11=0),"",IFERROR(O11/(L11*60*S11/(M11*36))*100,0)) -> 104.09588 | W11: =IF(O11="","",IFERROR(V11/O11*100,0)) -> 0 | AF11: =IF(O11="","",SUM(X11:AE11)) -> 0 | AG11: =IF(O11="","",IFERROR(AF11/O11*1000,0)) -> 0
A12: 7 | B12: 46288 | G12: STL005466 | H12: =IFERROR(INDEX('Operator Master'!$B$5:$B$504,MATCH(G12,'Operator Master'!$A$5:$A$504,0)),"") -> MD. ANOWAR HOSEN-3 | J12: 9 | K12: U2,U4,U5,U6,V2,V3,V4,V5,V6 | L12: 505.55556 | M12: 44.78 | N12: 1600 | O12: 1156 | P12: =IF(OR(N12="",O12=""),"",IFERROR(O12/N12*100,0)) -> 72.25 | Q12: 8 | R12: =IF(J12="","",Q12*J12) -> 72 | T12: =IF(OR(R12="",S12=""),"",IFERROR(S12/R12*100,0)) | U12: =IF(OR(O12="",L12="",M12="",S12="",M12=0),"",IFERROR(O12/(L12*60*S12/(M12*36))*100,0)) | W12: =IF(O12="","",IFERROR(V12/O12*100,0)) -> 0 | AF12: =IF(O12="","",SUM(X12:AE12)) -> 0 | AG12: =IF(O12="","",IFERROR(AF12/O12*1000,0)) -> 0
A13: 8 | B13: 46288 | G13: STL005489 | H13: =IFERROR(INDEX('Operator Master'!$B$5:$B$504,MATCH(G13,'Operator Master'!$A$5:$A$504,0)),"") -> MD. ALAM MIA | J13: 9 | K13: C1,C2,D1,D2,D3,E1,E2,F1,F2 | L13: 555.55556 | N13: 1750 | O13: 1255 | P13: =IF(OR(N13="",O13=""),"",IFERROR(O13/N13*100,0)) -> 71.714286 | Q13: 8 | R13: =IF(J13="","",Q13*J13) -> 72 | T13: =IF(OR(R13="",S13=""),"",IFERROR(S13/R13*100,0)) | U13: =IF(OR(O13="",L13="",M13="",S13="",M13=0),"",IFERROR(O13/(L13*60*S13/(M13*36))*100,0)) | W13: =IF(O13="","",IFERROR(V13/O13*100,0)) -> 0 | AF13: =IF(O13="","",SUM(X13:AE13)) -> 0 | AG13: =IF(O13="","",IFERROR(AF13/O13*1000,0)) -> 0
A14: 9 | B14: 46288 | G14: STL005490 | H14: =IFERROR(INDEX('Operator Master'!$B$5:$B$504,MATCH(G14,'Operator Master'!$A$5:$A$504,0)),"") -> MD. MOMINUL ISLAM | J14: 5 | K14: Q1,Q2,S1,S2,S3 | L14: 545 | M14: 41.8 | N14: 1100 | O14: 876 | P14: =IF(OR(N14="",O14=""),"",IFERROR(O14/N14*100,0)) -> 79.636364 | Q14: 8 | R14: =IF(J14="","",Q14*J14) -> 40 | T14: =IF(OR(R14="",S14=""),"",IFERROR(S14/R14*100,0)) | U14: =IF(OR(O14="",L14="",M14="",S14="",M14=0),"",IFERROR(O14/(L14*60*S14/(M14*36))*100,0)) | W14: =IF(O14="","",IFERROR(V14/O14*100,0)) -> 0 | AF14: =IF(O14="","",SUM(X14:AE14)) -> 0 | AG14: =IF(O14="","",IFERROR(AF14/O14*1000,0)) -> 0
A15: 10 | B15: 46288 | G15: STL005487 | H15: =IFERROR(INDEX('Operator Master'!$B$5:$B$504,MATCH(G15,'Operator Master'!$A$5:$A$504,0)),"") -> MD. JAHIDUL ISLAM HOWLADER | J15: 9 | K15: C3,C4,C5,C6,C7,D4,D5,D6,D7 | L15: 555.55556 | M15: 43.78 | N15: 1700 | O15: 1187 | P15: =IF(OR(N15="",O15=""),"",IFERROR(O15/N15*100,0)) -> 69.823529 | Q15: 8 | R15: =IF(J15="","",Q15*J15) -> 72 | T15: =IF(OR(R15="",S15=""),"",IFERROR(S15/R15*100,0)) | U15: =IF(OR(O15="",L15="",M15="",S15="",M15=0),"",IFERROR(O15/(L15*60*S15/(M15*36))*100,0)) | W15: =IF(O15="","",IFERROR(V15/O15*100,0)) -> 0 | AF15: =IF(O15="","",SUM(X15:AE15)) -> 0 | AG15: =IF(O15="","",IFERROR(AF15/O15*1000,0)) -> 0
A16: 11 | B16: 46288 | G16: STL005511 | H16: =IFERROR(INDEX('Operator Master'!$B$5:$B$504,MATCH(G16,'Operator Master'!$A$5:$A$504,0)),"") -> MD. RIPON MIA-2 | J16: 10 | K16: K6,L6,M3,M4,M5,M6,N3,N4,N5,N6 | L16: 530 | M16: 44.7 | N16: 1800 | O16: 1265 | P16: =IF(OR(N16="",O16=""),"",IFERROR(O16/N16*100,0)) -> 70.277778 | Q16: 8 | R16: =IF(J16="","",Q16*J16) -> 80 | T16: =IF(OR(R16="",S16=""),"",IFERROR(S16/R16*100,0)) | U16: =IF(OR(O16="",L16="",M16="",S16="",M16=0),"",IFERROR(O16/(L16*60*S16/(M16*36))*100,0)) | W16: =IF(O16="","",IFERROR(V16/O16*100,0)) -> 0 | AF16: =IF(O16="","",SUM(X16:AE16)) -> 0 | AG16: =IF(O16="","",IFERROR(AF16/O16*1000,0)) -> 0
A17: 12 | B17: 46288 | G17: STL005516 | H17: =IFERROR(INDEX('Operator Master'!$B$5:$B$504,MATCH(G17,'Operator Master'!$A$5:$A$504,0)),"") -> GOULAM RABBANI | J17: 10 | K17: E3,E4,E5,E6,E7,F3,F4,F5,F6,F7 | L17: 555 | M17: 41.9 | N17: 1700 | O17: 1292 | P17: =IF(OR(N17="",O17=""),"",IFERROR(O17/N17*100,0)) -> 76 | Q17: 8 | R17: =IF(J17="","",Q17*J17) -> 80 | T17: =IF(OR(R17="",S17=""),"",IFERROR(S17/R17*100,0)) | U17: =IF(OR(O17="",L17="",M17="",S17="",M17=0),"",IFERROR(O17/(L17*60*S17/(M17*36))*100,0)) | W17: =IF(O17="","",IFERROR(V17/O17*100,0)) -> 0 | AF17: =IF(O17="","",SUM(X17:AE17)) -> 0 | AG17: =IF(O17="","",IFERROR(AF17/O17*1000,0)) -> 0
A18: 13 | B18: 46288 | G18: STL005513 | H18: =IFERROR(INDEX('Operator Master'!$B$5:$B$504,MATCH(G18,'Operator Master'!$A$5:$A$504,0)),"") -> MD. HABIBUR RAHMAN | J18: 9 | K18: M1,M2,N1,P1,P2,P3,O1,O2,O3 | L18: 541.66667 | M18: 42.44 | N18: 1700 | O18: 1168 | P18: =IF(OR(N18="",O18=""),"",IFERROR(O18/N18*100,0)) -> 68.705882 | Q18: 8 | R18: =IF(J18="","",Q18*J18) -> 72 | T18: =IF(OR(R18="",S18=""),"",IFERROR(S18/R18*100,0)) | U18: =IF(OR(O18="",L18="",M18="",S18="",M18=0),"",IFERROR(O18/(L18*60*S18/(M18*36))*100,0)) | W18: =IF(O18="","",IFERROR(V18/O18*100,0)) -> 0 | AF18: =IF(O18="","",SUM(X18:AE18)) -> 0 | AG18: =IF(O18="","",IFERROR(AF18/O18*1000,0)) -> 0
A19: 14 | B19: 46288 | G19: STL005520 | H19: =IFERROR(INDEX('Operator Master'!$B$5:$B$504,MATCH(G19,'Operator Master'!$A$5:$A$504,0)),"") -> MD. SAIFUL ISLAM-3 | J19: 9 | K19: I1,I2,I3,I4,J1,J2,J3,J4,J5 | L19: 525 | M19: 39.22 | N19: 1600 | P19: =IF(OR(N19="",O19=""),"",IFERROR(O19/N19*100,0)) | Q19: 8 | R19: =IF(J19="","",Q19*J19) -> 72 | T19: =IF(OR(R19="",S19=""),"",IFERROR(S19/R19*100,0)) | U19: =IF(OR(O19="",L19="",M19="",S19="",M19=0),"",IFERROR(O19/(L19*60*S19/(M19*36))*100,0)) | W19: =IF(O19="","",IFERROR(V19/O19*100,0)) | AF19: =IF(O19="","",SUM(X19:AE19)) | AG19: =IF(O19="","",IFERROR(AF19/O19*1000,0))
A20: 15 | B20: 46288 | G20: STL005488 | H20: =IFERROR(INDEX('Operator Master'!$B$5:$B$504,MATCH(G20,'Operator Master'!$A$5:$A$504,0)),"") -> MD. JAKIR HOSEN | J20: 10 | K20: K1,K2,K3,K4,K5,L1,L2,L3,L4,L5 | L20: 537.5 | M20: 41.6 | N20: 1800 | P20: =IF(OR(N20="",O20=""),"",IFERROR(O20/N20*100,0)) | Q20: 8 | R20: =IF(J20="","",Q20*J20) -> 80 | T20: =IF(OR(R20="",S20=""),"",IFERROR(S20/R20*100,0)) | U20: =IF(OR(O20="",L20="",M20="",S20="",M20=0),"",IFERROR(O20/(L20*60*S20/(M20*36))*100,0)) | W20: =IF(O20="","",IFERROR(V20/O20*100,0)) | AF20: =IF(O20="","",SUM(X20:AE20)) | AG20: =IF(O20="","",IFERROR(AF20/O20*1000,0))
A21: 16 | B21: 46288 | G21: STL005916 | H21: =IFERROR(INDEX('Operator Master'!$B$5:$B$504,MATCH(G21,'Operator Master'!$A$5:$A$504,0)),"") -> AZIZUL HAQUE | J21: 8 | K21: C1,C2,D1,D2,E1,E2,F1,F2 | L21: 559.375 | M21: 41.75 | N21: 1500 | P21: =IF(OR(N21="",O21=""),"",IFERROR(O21/N21*100,0)) | Q21: 8 | R21: =IF(J21="","",Q21*J21) -> 64 | T21: =IF(OR(R21="",S21=""),"",IFERROR(S21/R21*100,0)) | U21: =IF(OR(O21="",L21="",M21="",S21="",M21=0),"",IFERROR(O21/(L21*60*S21/(M21*36))*100,0)) | W21: =IF(O21="","",IFERROR(V21/O21*100,0)) | AF21: =IF(O21="","",SUM(X21:AE21)) | AG21: =IF(O21="","",IFERROR(AF21/O21*1000,0))
A22: 17 | B22: 46288 | G22: STL007346 | H22: =IFERROR(INDEX('Operator Master'!$B$5:$B$504,MATCH(G22,'Operator Master'!$A$5:$A$504,0)),"") -> MD. ANARUL ISLAM | J22: 8 | K22: S2,S3,S4,S5,T2,T4,T5,T6 | L22: 553.125 | M22: 41.25 | N22: 1600 | P22: =IF(OR(N22="",O22=""),"",IFERROR(O22/N22*100,0)) | Q22: 8 | R22: =IF(J22="","",Q22*J22) -> 64 | T22: =IF(OR(R22="",S22=""),"",IFERROR(S22/R22*100,0)) | U22: =IF(OR(O22="",L22="",M22="",S22="",M22=0),"",IFERROR(O22/(L22*60*S22/(M22*36))*100,0)) | W22: =IF(O22="","",IFERROR(V22/O22*100,0)) | AF22: =IF(O22="","",SUM(X22:AE22)) | AG22: =IF(O22="","",IFERROR(AF22/O22*1000,0))
A23: 18 | B23: 46288 | G23: STL007421 | H23: =IFERROR(INDEX('Operator Master'!$B$5:$B$504,MATCH(G23,'Operator Master'!$A$5:$A$504,0)),"") -> MD. ROSHID | J23: 9 | K23: K6,L6,M3,M4,M5,M6,N3,N5,N6 | L23: 533.33333 | M23: 44.67 | N23: 1600 | P23: =IF(OR(N23="",O23=""),"",IFERROR(O23/N23*100,0)) | Q23: 8 | R23: =IF(J23="","",Q23*J23) -> 72 | T23: =IF(OR(R23="",S23=""),"",IFERROR(S23/R23*100,0)) | U23: =IF(OR(O23="",L23="",M23="",S23="",M23=0),"",IFERROR(O23/(L23*60*S23/(M23*36))*100,0)) | W23: =IF(O23="","",IFERROR(V23/O23*100,0)) | AF23: =IF(O23="","",SUM(X23:AE23)) | AG23: =IF(O23="","",IFERROR(AF23/O23*1000,0))
A24: 19 | B24: 46288 | G24: STL007504 | H24: =IFERROR(INDEX('Operator Master'!$B$5:$B$504,MATCH(G24,'Operator Master'!$A$5:$A$504,0)),"") -> MD. AZIM | J24: 10 | K24: C3,C4,C5,C6,C7,D3,D4,D5,D6,D7 | L24: 552.5 | M24: 43.4 | N24: 1800 | P24: =IF(OR(N24="",O24=""),"",IFERROR(O24/N24*100,0)) | Q24: 8 | R24: =IF(J24="","",Q24*J24) -> 80 | T24: =IF(OR(R24="",S24=""),"",IFERROR(S24/R24*100,0)) | U24: =IF(OR(O24="",L24="",M24="",S24="",M24=0),"",IFERROR(O24/(L24*60*S24/(M24*36))*100,0)) | W24: =IF(O24="","",IFERROR(V24/O24*100,0)) | AF24: =IF(O24="","",SUM(X24:AE24)) | AG24: =IF(O24="","",IFERROR(AF24/O24*1000,0))
A25: 20 | B25: 46288 | G25: STL005458 | H25: =IFERROR(INDEX('Operator Master'!$B$5:$B$504,MATCH(G25,'Operator Master'!$A$5:$A$504,0)),"") -> MD. MOTALEB HOSEN | J25: 10 | K25: G1,G2,G3,G4,G5,H1,H2,H3,H4,H5 | L25: 527.5 | M25: 44.8 | N25: 1600 | P25: =IF(OR(N25="",O25=""),"",IFERROR(O25/N25*100,0)) | Q25: 8 | R25: =IF(J25="","",Q25*J25) -> 80 | T25: =IF(OR(R25="",S25=""),"",IFERROR(S25/R25*100,0)) | U25: =IF(OR(O25="",L25="",M25="",S25="",M25=0),"",IFERROR(O25/(L25*60*S25/(M25*36))*100,0)) | W25: =IF(O25="","",IFERROR(V25/O25*100,0)) | AF25: =IF(O25="","",SUM(X25:AE25)) | AG25: =IF(O25="","",IFERROR(AF25/O25*1000,0))
A26: 21 | B26: 46288 | G26: STL005473 | H26: =IFERROR(INDEX('Operator Master'!$B$5:$B$504,MATCH(G26,'Operator Master'!$A$5:$A$504,0)),"") -> MD. KAWSAR ALI | J26: 10 | K26: E3,E4,E5,E6,E7,F3,F4,F5,F6,F7 | L26: 555 | M26: 41.8 | N26: 1900 | P26: =IF(OR(N26="",O26=""),"",IFERROR(O26/N26*100,0)) | Q26: 8 | R26: =IF(J26="","",Q26*J26) -> 80 | T26: =IF(OR(R26="",S26=""),"",IFERROR(S26/R26*100,0)) | U26: =IF(OR(O26="",L26="",M26="",S26="",M26=0),"",IFERROR(O26/(L26*60*S26/(M26*36))*100,0)) | W26: =IF(O26="","",IFERROR(V26/O26*100,0)) | AF26: =IF(O26="","",SUM(X26:AE26)) | AG26: =IF(O26="","",IFERROR(AF26/O26*1000,0))
A27: 22 | B27: 46288 | G27: STL005474 | H27: =IFERROR(INDEX('Operator Master'!$B$5:$B$504,MATCH(G27,'Operator Master'!$A$5:$A$504,0)),"") -> MD. FARMAN ALI | J27: 9 | K27: G6,G7,H6,H7,I5,I6,I7,J6,J7 | L27: 569.44444 | M27: 42.22 | N27: 1700 | P27: =IF(OR(N27="",O27=""),"",IFERROR(O27/N27*100,0)) | Q27: 8 | R27: =IF(J27="","",Q27*J27) -> 72 | T27: =IF(OR(R27="",S27=""),"",IFERROR(S27/R27*100,0)) | U27: =IF(OR(O27="",L27="",M27="",S27="",M27=0),"",IFERROR(O27/(L27*60*S27/(M27*36))*100,0)) | W27: =IF(O27="","",IFERROR(V27/O27*100,0)) | AF27: =IF(O27="","",SUM(X27:AE27)) | AG27: =IF(O27="","",IFERROR(AF27/O27*1000,0))
A28: 23 | B28: 46288 | G28: STL005478 | H28: =IFERROR(INDEX('Operator Master'!$B$5:$B$504,MATCH(G28,'Operator Master'!$A$5:$A$504,0)),"") -> MD. JULHAS UDDIN | J28: 9 | K28: U2,U3,U5,U6,V2,V3,V4,V5,V6 | L28: 505.55556 | M28: 44.81 | N28: 1500 | P28: =IF(OR(N28="",O28=""),"",IFERROR(O28/N28*100,0)) | Q28: 8 | R28: =IF(J28="","",Q28*J28) -> 72 | T28: =IF(OR(R28="",S28=""),"",IFERROR(S28/R28*100,0)) | U28: =IF(OR(O28="",L28="",M28="",S28="",M28=0),"",IFERROR(O28/(L28*60*S28/(M28*36))*100,0)) | W28: =IF(O28="","",IFERROR(V28/O28*100,0)) | AF28: =IF(O28="","",SUM(X28:AE28)) | AG28: =IF(O28="","",IFERROR(AF28/O28*1000,0))
A29: 24 | B29: 46288 | G29: STL005493 | H29: =IFERROR(INDEX('Operator Master'!$B$5:$B$504,MATCH(G29,'Operator Master'!$A$5:$A$504,0)),"") -> MD. ABDUL AWAL | J29: 7 | K29: Q1,Q2,Q4,R1,R3,R4,S1 | L29: 539.28571 | M29: 40.43 | N29: 1400 | P29: =IF(OR(N29="",O29=""),"",IFERROR(O29/N29*100,0)) | Q29: 8 | R29: =IF(J29="","",Q29*J29) -> 56 | T29: =IF(OR(R29="",S29=""),"",IFERROR(S29/R29*100,0)) | U29: =IF(OR(O29="",L29="",M29="",S29="",M29=0),"",IFERROR(O29/(L29*60*S29/(M29*36))*100,0)) | W29: =IF(O29="","",IFERROR(V29/O29*100,0)) | AF29: =IF(O29="","",SUM(X29:AE29)) | AG29: =IF(O29="","",IFERROR(AF29/O29*1000,0))
A30: 25 | B30: 46288 | G30: STL005469 | H30: =IFERROR(INDEX('Operator Master'!$B$5:$B$504,MATCH(G30,'Operator Master'!$A$5:$A$504,0)),"") -> MD. DULU MIA | J30: 8 | K30: M1,M2,N1,O2,O3,P1,P2,P3 | L30: 540.625 | M30: 42.63 | N30: 1500 | P30: =IF(OR(N30="",O30=""),"",IFERROR(O30/N30*100,0)) | Q30: 8 | R30: =IF(J30="","",Q30*J30) -> 64 | T30: =IF(OR(R30="",S30=""),"",IFERROR(S30/R30*100,0)) | U30: =IF(OR(O30="",L30="",M30="",S30="",M30=0),"",IFERROR(O30/(L30*60*S30/(M30*36))*100,0)) | W30: =IF(O30="","",IFERROR(V30/O30*100,0)) | AF30: =IF(O30="","",SUM(X30:AE30)) | AG30: =IF(O30="","",IFERROR(AF30/O30*1000,0))
A31: 26 | B31: 46288 | G31: STL005464 | H31: =IFERROR(INDEX('Operator Master'!$B$5:$B$504,MATCH(G31,'Operator Master'!$A$5:$A$504,0)),"") -> SREE SUSANTO CHANDRA | J31: 8 | K31: O5,O6,P4,P5,Q5,Q6,R5,R6 | L31: 543.75 | M31: 42.5 | N31: 1500 | P31: =IF(OR(N31="",O31=""),"",IFERROR(O31/N31*100,0)) | Q31: 8 | R31: =IF(J31="","",Q31*J31) -> 64 | T31: =IF(OR(R31="",S31=""),"",IFERROR(S31/R31*100,0)) | U31: =IF(OR(O31="",L31="",M31="",S31="",M31=0),"",IFERROR(O31/(L31*60*S31/(M31*36))*100,0)) | W31: =IF(O31="","",IFERROR(V31/O31*100,0)) | AF31: =IF(O31="","",SUM(X31:AE31)) | AG31: =IF(O31="","",IFERROR(AF31/O31*1000,0))
A32: 27 | B32: 46288 | G32: STL005471 | H32: =IFERROR(INDEX('Operator Master'!$B$5:$B$504,MATCH(G32,'Operator Master'!$A$5:$A$504,0)),"") -> MD. ASHRAFUL ISLAM | L32: 545 | M32: 41.8 | P32: =IF(OR(N32="",O32=""),"",IFERROR(O32/N32*100,0)) | Q32: 8 | R32: =IF(J32="","",Q32*J32) | T32: =IF(OR(R32="",S32=""),"",IFERROR(S32/R32*100,0)) | U32: =IF(OR(O32="",L32="",M32="",S32="",M32=0),"",IFERROR(O32/(L32*60*S32/(M32*36))*100,0)) | W32: =IF(O32="","",IFERROR(V32/O32*100,0)) | AF32: =IF(O32="","",SUM(X32:AE32)) | AG32: =IF(O32="","",IFERROR(AF32/O32*1000,0))
A33: 28 | B33: 46288 | G33: STL005525 | H33: =IFERROR(INDEX('Operator Master'!$B$5:$B$504,MATCH(G33,'Operator Master'!$A$5:$A$504,0)),"") -> MD. ASRAF AKANDA | L33: 555.55556 | M33: 43.78 | P33: =IF(OR(N33="",O33=""),"",IFERROR(O33/N33*100,0)) | Q33: 8 | R33: =IF(J33="","",Q33*J33) | T33: =IF(OR(R33="",S33=""),"",IFERROR(S33/R33*100,0)) | U33: =IF(OR(O33="",L33="",M33="",S33="",M33=0),"",IFERROR(O33/(L33*60*S33/(M33*36))*100,0)) | W33: =IF(O33="","",IFERROR(V33/O33*100,0)) | AF33: =IF(O33="","",SUM(X33:AE33)) | AG33: =IF(O33="","",IFERROR(AF33/O33*1000,0))
A34: 29 | B34: 46288 | G34: STL005503 | H34: =IFERROR(INDEX('Operator Master'!$B$5:$B$504,MATCH(G34,'Operator Master'!$A$5:$A$504,0)),"") -> MD. JIHADUZZAMAN (JIAD) | L34: 530 | M34: 44.7 | P34: =IF(OR(N34="",O34=""),"",IFERROR(O34/N34*100,0)) | Q34: 8 | R34: =IF(J34="","",Q34*J34) | T34: =IF(OR(R34="",S34=""),"",IFERROR(S34/R34*100,0)) | U34: =IF(OR(O34="",L34="",M34="",S34="",M34=0),"",IFERROR(O34/(L34*60*S34/(M34*36))*100,0)) | W34: =IF(O34="","",IFERROR(V34/O34*100,0)) | AF34: =IF(O34="","",SUM(X34:AE34)) | AG34: =IF(O34="","",IFERROR(AF34/O34*1000,0))
A35: 30 | B35: 46288 | G35: STL005519 | H35: =IFERROR(INDEX('Operator Master'!$B$5:$B$504,MATCH(G35,'Operator Master'!$A$5:$A$504,0)),"") -> MD. MOZNU SHEKH | L35: 555 | M35: 41.9 | P35: =IF(OR(N35="",O35=""),"",IFERROR(O35/N35*100,0)) | Q35: 8 | R35: =IF(J35="","",Q35*J35) | T35: =IF(OR(R35="",S35=""),"",IFERROR(S35/R35*100,0)) | U35: =IF(OR(O35="",L35="",M35="",S35="",M35=0),"",IFERROR(O35/(L35*60*S35/(M35*36))*100,0)) | W35: =IF(O35="","",IFERROR(V35/O35*100,0)) | AF35: =IF(O35="","",SUM(X35:AE35)) | AG35: =IF(O35="","",IFERROR(AF35/O35*1000,0))
A36: 31 | B36: 46288 | G36: STL005500 | H36: =IFERROR(INDEX('Operator Master'!$B$5:$B$504,MATCH(G36,'Operator Master'!$A$5:$A$504,0)),"") -> MD. AMINUR ISLAM | L36: 541.66667 | M36: 42.44 | P36: =IF(OR(N36="",O36=""),"",IFERROR(O36/N36*100,0)) | Q36: 8 | R36: =IF(J36="","",Q36*J36) | T36: =IF(OR(R36="",S36=""),"",IFERROR(S36/R36*100,0)) | U36: =IF(OR(O36="",L36="",M36="",S36="",M36=0),"",IFERROR(O36/(L36*60*S36/(M36*36))*100,0)) | W36: =IF(O36="","",IFERROR(V36/O36*100,0)) | AF36: =IF(O36="","",SUM(X36:AE36)) | AG36: =IF(O36="","",IFERROR(AF36/O36*1000,0))
A37: 32 | B37: 46288 | G37: STL006681 | H37: =IFERROR(INDEX('Operator Master'!$B$5:$B$504,MATCH(G37,'Operator Master'!$A$5:$A$504,0)),"") -> MD. BABUL MIAH | L37: 525 | M37: 39.22 | P37: =IF(OR(N37="",O37=""),"",IFERROR(O37/N37*100,0)) | Q37: 8 | R37: =IF(J37="","",Q37*J37) | T37: =IF(OR(R37="",S37=""),"",IFERROR(S37/R37*100,0)) | U37: =IF(OR(O37="",L37="",M37="",S37="",M37=0),"",IFERROR(O37/(L37*60*S37/(M37*36))*100,0)) | W37: =IF(O37="","",IFERROR(V37/O37*100,0)) | AF37: =IF(O37="","",SUM(X37:AE37)) | AG37: =IF(O37="","",IFERROR(AF37/O37*1000,0))
A38: 33 | B38: 46288 | G38: STL006736 | H38: =IFERROR(INDEX('Operator Master'!$B$5:$B$504,MATCH(G38,'Operator Master'!$A$5:$A$504,0)),"") -> MD. ROFIKUL ISLAM | L38: 537.5 | M38: 41.6 | P38: =IF(OR(N38="",O38=""),"",IFERROR(O38/N38*100,0)) | Q38: 8 | R38: =IF(J38="","",Q38*J38) | T38: =IF(OR(R38="",S38=""),"",IFERROR(S38/R38*100,0)) | U38: =IF(OR(O38="",L38="",M38="",S38="",M38=0),"",IFERROR(O38/(L38*60*S38/(M38*36))*100,0)) | W38: =IF(O38="","",IFERROR(V38/O38*100,0)) | AF38: =IF(O38="","",SUM(X38:AE38)) | AG38: =IF(O38="","",IFERROR(AF38/O38*1000,0))
A39: 34 | B39: 46288 | G39: STL007340 | H39: =IFERROR(INDEX('Operator Master'!$B$5:$B$504,MATCH(G39,'Operator Master'!$A$5:$A$504,0)),"") -> MD. AMINUL ISLAM-2 | L39: 559.375 | M39: 41.75 | P39: =IF(OR(N39="",O39=""),"",IFERROR(O39/N39*100,0)) | Q39: 8 | R39: =IF(J39="","",Q39*J39) | T39: =IF(OR(R39="",S39=""),"",IFERROR(S39/R39*100,0)) | U39: =IF(OR(O39="",L39="",M39="",S39="",M39=0),"",IFERROR(O39/(L39*60*S39/(M39*36))*100,0)) | W39: =IF(O39="","",IFERROR(V39/O39*100,0)) | AF39: =IF(O39="","",SUM(X39:AE39)) | AG39: =IF(O39="","",IFERROR(AF39/O39*1000,0))
A40: 35 | B40: 46288 | G40: STL007341 | H40: =IFERROR(INDEX('Operator Master'!$B$5:$B$504,MATCH(G40,'Operator Master'!$A$5:$A$504,0)),"") -> MD. JONY ALOM | L40: 553.125 | M40: 41.25 | P40: =IF(OR(N40="",O40=""),"",IFERROR(O40/N40*100,0)) | Q40: 8 | R40: =IF(J40="","",Q40*J40) | T40: =IF(OR(R40="",S40=""),"",IFERROR(S40/R40*100,0)) | U40: =IF(OR(O40="",L40="",M40="",S40="",M40=0),"",IFERROR(O40/(L40*60*S40/(M40*36))*100,0)) | W40: =IF(O40="","",IFERROR(V40/O40*100,0)) | AF40: =IF(O40="","",SUM(X40:AE40)) | AG40: =IF(O40="","",IFERROR(AF40/O40*1000,0))
A41: 36 | B41: 46288 | G41: STL007502 | H41: =IFERROR(INDEX('Operator Master'!$B$5:$B$504,MATCH(G41,'Operator Master'!$A$5:$A$504,0)),"") -> MD. HELIM ISLAM | L41: 533.33333 | M41: 44.67 | P41: =IF(OR(N41="",O41=""),"",IFERROR(O41/N41*100,0)) | Q41: 8 | R41: =IF(J41="","",Q41*J41) | T41: =IF(OR(R41="",S41=""),"",IFERROR(S41/R41*100,0)) | U41: =IF(OR(O41="",L41="",M41="",S41="",M41=0),"",IFERROR(O41/(L41*60*S41/(M41*36))*100,0)) | W41: =IF(O41="","",IFERROR(V41/O41*100,0)) | AF41: =IF(O41="","",SUM(X41:AE41)) | AG41: =IF(O41="","",IFERROR(AF41/O41*1000,0))
...

Sheet Fault & Downtime Entry
A1: STL FU — WEAVING | FAULT & DOWNTIME ENTRY
A3: ENTRY RULE: one row = one fault event/grouped event. Record frequency as occurrences, affected fabric in yards, and downtime in minutes.
A4: Use Responsibility to distinguish Operator / Supervisor / Machine / Material / Process / Other. This sheet is separate from the daily KPI entry for easier use.
A5: Fault Log ID | B5: Date | C5: Actual Shift | D5: Loom No | E5: Operator ID | F5: Operator Name | G5: Fault Code | H5: Fault Category | I5: Fault Name | J5: Frequency | K5: Affected Yds | L5: Downtime Min | M5: Severity | N5: Responsibility | O5: Root Cause / Corrective Action
A6: 1 | F6: =IFERROR(INDEX('Operator Master'!$B$5:$B$504,MATCH(E6,'Operator Master'!$A$5:$A$504,0)),"") | H6: =IFERROR(INDEX('Fault Master'!$B$5:$B$104,MATCH(G6,'Fault Master'!$A$5:$A$104,0)),"") | I6: =IFERROR(INDEX('Fault Master'!$C$5:$C$104,MATCH(G6,'Fault Master'!$A$5:$A$104,0)),"") | M6: =IFERROR(INDEX('Fault Master'!$D$5:$D$104,MATCH(G6,'Fault Master'!$A$5:$A$104,0)),"")
A7: 2 | F7: =IFERROR(INDEX('Operator Master'!$B$5:$B$504,MATCH(E7,'Operator Master'!$A$5:$A$504,0)),"") | H7: =IFERROR(INDEX('Fault Master'!$B$5:$B$104,MATCH(G7,'Fault Master'!$A$5:$A$104,0)),"") | I7: =IFERROR(INDEX('Fault Master'!$C$5:$C$104,MATCH(G7,'Fault Master'!$A$5:$A$104,0)),"") | M7: =IFERROR(INDEX('Fault Master'!$D$5:$D$104,MATCH(G7,'Fault Master'!$A$5:$A$104,0)),"")
A8: 3 | F8: =IFERROR(INDEX('Operator Master'!$B$5:$B$504,MATCH(E8,'Operator Master'!$A$5:$A$504,0)),"") | H8: =IFERROR(INDEX('Fault Master'!$B$5:$B$104,MATCH(G8,'Fault Master'!$A$5:$A$104,0)),"") | I8: =IFERROR(INDEX('Fault Master'!$C$5:$C$104,MATCH(G8,'Fault Master'!$A$5:$A$104,0)),"") | M8: =IFERROR(INDEX('Fault Master'!$D$5:$D$104,MATCH(G8,'Fault Master'!$A$5:$A$104,0)),"")
A9: 4 | F9: =IFERROR(INDEX('Operator Master'!$B$5:$B$504,MATCH(E9,'Operator Master'!$A$5:$A$504,0)),"") | H9: =IFERROR(INDEX('Fault Master'!$B$5:$B$104,MATCH(G9,'Fault Master'!$A$5:$A$104,0)),"") | I9: =IFERROR(INDEX('Fault Master'!$C$5:$C$104,MATCH(G9,'Fault Master'!$A$5:$A$104,0)),"") | M9: =IFERROR(INDEX('Fault Master'!$D$5:$D$104,MATCH(G9,'Fault Master'!$A$5:$A$104,0)),"")
A10: 5 | F10: =IFERROR(INDEX('Operator Master'!$B$5:$B$504,MATCH(E10,'Operator Master'!$A$5:$A$504,0)),"") | H10: =IFERROR(INDEX('Fault Master'!$B$5:$B$104,MATCH(G10,'Fault Master'!$A$5:$A$104,0)),"") | I10: =IFERROR(INDEX('Fault Master'!$C$5:$C$104,MATCH(G10,'Fault Master'!$A$5:$A$104,0)),"") | M10: =IFERROR(INDEX('Fault Master'!$D$5:$D$104,MATCH(G10,'Fault Master'!$A$5:$A$104,0)),"")
A11: 6 | F11: =IFERROR(INDEX('Operator Master'!$B$5:$B$504,MATCH(E11,'Operator Master'!$A$5:$A$504,0)),"") | H11: =IFERROR(INDEX('Fault Master'!$B$5:$B$104,MATCH(G11,'Fault Master'!$A$5:$A$104,0)),"") | I11: =IFERROR(INDEX('Fault Master'!$C$5:$C$104,MATCH(G11,'Fault Master'!$A$5:$A$104,0)),"") | M11: =IFERROR(INDEX('Fault Master'!$D$5:$D$104,MATCH(G11,'Fault Master'!$A$5:$A$104,0)),"")
A12: 7 | F12: =IFERROR(INDEX('Operator Master'!$B$5:$B$504,MATCH(E12,'Operator Master'!$A$5:$A$504,0)),"") | H12: =IFERROR(INDEX('Fault Master'!$B$5:$B$104,MATCH(G12,'Fault Master'!$A$5:$A$104,0)),"") | I12: =IFERROR(INDEX('Fault Master'!$C$5:$C$104,MATCH(G12,'Fault Master'!$A$5:$A$104,0)),"") | M12: =IFERROR(INDEX('Fault Master'!$D$5:$D$104,MATCH(G12,'Fault Master'!$A$5:$A$104,0)),"")
A13: 8 | F13: =IFERROR(INDEX('Operator Master'!$B$5:$B$504,MATCH(E13,'Operator Master'!$A$5:$A$504,0)),"") | H13: =IFERROR(INDEX('Fault Master'!$B$5:$B$104,MATCH(G13,'Fault Master'!$A$5:$A$104,0)),"") | I13: =IFERROR(INDEX('Fault Master'!$C$5:$C$104,MATCH(G13,'Fault Master'!$A$5:$A$104,0)),"") | M13: =IFERROR(INDEX('Fault Master'!$D$5:$D$104,MATCH(G13,'Fault Master'!$A$5:$A$104,0)),"")
A14: 9 | F14: =IFERROR(INDEX('Operator Master'!$B$5:$B$504,MATCH(E14,'Operator Master'!$A$5:$A$504,0)),"") | H14: =IFERROR(INDEX('Fault Master'!$B$5:$B$104,MATCH(G14,'Fault Master'!$A$5:$A$104,0)),"") | I14: =IFERROR(INDEX('Fault Master'!$C$5:$C$104,MATCH(G14,'Fault Master'!$A$5:$A$104,0)),"") | M14: =IFERROR(INDEX('Fault Master'!$D$5:$D$104,MATCH(G14,'Fault Master'!$A$5:$A$104,0)),"")
A15: 10 | F15: =IFERROR(INDEX('Operator Master'!$B$5:$B$504,MATCH(E15,'Operator Master'!$A$5:$A$504,0)),"") | H15: =IFERROR(INDEX('Fault Master'!$B$5:$B$104,MATCH(G15,'Fault Master'!$A$5:$A$104,0)),"") | I15: =IFERROR(INDEX('Fault Master'!$C$5:$C$104,MATCH(G15,'Fault Master'!$A$5:$A$104,0)),"") | M15: =IFERROR(INDEX('Fault Master'!$D$5:$D$104,MATCH(G15,'Fault Master'!$A$5:$A$104,0)),"")
A16: 11 | F16: =IFERROR(INDEX('Operator Master'!$B$5:$B$504,MATCH(E16,'Operator Master'!$A$5:$A$504,0)),"") | H16: =IFERROR(INDEX('Fault Master'!$B$5:$B$104,MATCH(G16,'Fault Master'!$A$5:$A$104,0)),"") | I16: =IFERROR(INDEX('Fault Master'!$C$5:$C$104,MATCH(G16,'Fault Master'!$A$5:$A$104,0)),"") | M16: =IFERROR(INDEX('Fault Master'!$D$5:$D$104,MATCH(G16,'Fault Master'!$A$5:$A$104,0)),"")
A17: 12 | F17: =IFERROR(INDEX('Operator Master'!$B$5:$B$504,MATCH(E17,'Operator Master'!$A$5:$A$504,0)),"") | H17: =IFERROR(INDEX('Fault Master'!$B$5:$B$104,MATCH(G17,'Fault Master'!$A$5:$A$104,0)),"") | I17: =IFERROR(INDEX('Fault Master'!$C$5:$C$104,MATCH(G17,'Fault Master'!$A$5:$A$104,0)),"") | M17: =IFERROR(INDEX('Fault Master'!$D$5:$D$104,MATCH(G17,'Fault Master'!$A$5:$A$104,0)),"")
... A1005: 1000 | F1005: =IFERROR(INDEX('Operator Master'!$B$5:$B$504,MATCH(E1005,'Operator Master'!$A$5:$A$504,0)),"") | H1005: =IFERROR(INDEX('Fault Master'!$B$5:$B$104,MATCH(G1005,'Fault Master'!$A$5:$A$104,0)),"") | I1005: =IFERROR(INDEX('Fault Master'!$C$5:$C$104,MATCH(G1005,'Fault Master'!$A$5:$A$104,0)),"") | M1005: =IFERROR(INDEX('Fault Master'!$D$5:$D$104,MATCH(G1005,'Fault Master'!$A$5:$A$104,0)),"")

Sheet Operator Master
A1: STL FU — WEAVING | OPERATOR MASTER
A2: Permanent employee master. Shift is NOT stored here because operators rotate. Maintain the weekly plan in Shift Roster.
A4: Operator ID | B4: Operator Name | C4: Designation | D4: Department | E4: Joining Date | F4: Status | G4: Remarks
A5: STL005494 | B5: MD. MAHABUB ALAM | C5: Weaving Operator | D5: Weaving | F5: No
A6: STL005476 | B6: MD. RIPU MIAH | C6: Weaving Operator | D6: Weaving | F6: Yes
A7: STL005492 | B7: MD. MINHAZ ALI | C7: Weaving Operator | D7: Weaving | F7: Yes
A8: STL005502 | B8: MD. FORIDUL ISLAM | C8: Weaving Operator | D8: Weaving | F8: Yes
A9: STL005507 | B9: MD. SAIFUL ISLAM-2 | C9: Weaving Operator | D9: Weaving | F9: No
A10: STL005510 | B10: MD. ZIAUL HAQUE | C10: Weaving Operator | D10: Weaving | F10: Yes
A11: STL005466 | B11: MD. ANOWAR HOSEN-3 | C11: Weaving Operator | D11: Weaving | F11: No
A12: STL005489 | B12: MD. ALAM MIA | C12: Weaving Operator | D12: Weaving | F12: Yes
A13: STL005490 | B13: MD. MOMINUL ISLAM | C13: Weaving Operator | D13: Weaving | F13: Yes
A14: STL005487 | B14: MD. JAHIDUL ISLAM HOWLADER | C14: Weaving Operator | D14: Weaving | F14: Yes
A15: STL005511 | B15: MD. RIPON MIA-2 | C15: Weaving Operator | D15: Weaving | F15: Yes
A16: STL005516 | B16: GOULAM RABBANI | C16: Weaving Operator | D16: Weaving | F16: Yes
... A60: STL007425 | B60: MD. ALOM ISLAM | C60: Weaving Operator | D60: Weaving | F60: Yes
D61: Weaving | F61: Yes
D62: Weaving | F62: Yes
D63: Weaving | F63: Yes
D64: Weaving | F64: Yes
D65: Weaving | F65: Yes
D66: Weaving | F66: Yes
D67: Weaving | F67: Yes
D68: Weaving | F68: Yes
D69: Weaving | F69: Yes
D70: Weaving | F70: Yes
D71: Weaving | F71: Yes
D72: Weaving | F72: Yes
... D504: Weaving | F504: Yes

Sheet Shift Roster
A1: STL FU — WEAVING | WEEKLY SHIFT ROSTER
A2: Planned schedule only. Do not overwrite the roster when an actual shift changes; record the actual shift in Data Entry.
A4: Week Start | B4: Week End | C4: Operator ID | D4: Operator Name | E4: Planned Shift | F4: Supervisor | G4: Remarks
B5: =IF(A5="","",A5+6) | D5: =IFERROR(INDEX('Operator Master'!$B$5:$B$504,MATCH(C5,'Operator Master'!$A$5:$A$504,0)),"")
B6: =IF(A6="","",A6+6) | D6: =IFERROR(INDEX('Operator Master'!$B$5:$B$504,MATCH(C6,'Operator Master'!$A$5:$A$504,0)),"")
B7: =IF(A7="","",A7+6) | D7: =IFERROR(INDEX('Operator Master'!$B$5:$B$504,MATCH(C7,'Operator Master'!$A$5:$A$504,0)),"")
B8: =IF(A8="","",A8+6) | D8: =IFERROR(INDEX('Operator Master'!$B$5:$B$504,MATCH(C8,'Operator Master'!$A$5:$A$504,0)),"")
B9: =IF(A9="","",A9+6) | D9: =IFERROR(INDEX('Operator Master'!$B$5:$B$504,MATCH(C9,'Operator Master'!$A$5:$A$504,0)),"")
B10: =IF(A10="","",A10+6) | D10: =IFERROR(INDEX('Operator Master'!$B$5:$B$504,MATCH(C10,'Operator Master'!$A$5:$A$504,0)),"")
B11: =IF(A11="","",A11+6) | D11: =IFERROR(INDEX('Operator Master'!$B$5:$B$504,MATCH(C11,'Operator Master'!$A$5:$A$504,0)),"")
B12: =IF(A12="","",A12+6) | D12: =IFERROR(INDEX('Operator Master'!$B$5:$B$504,MATCH(C12,'Operator Master'!$A$5:$A$504,0)),"")
B13: =IF(A13="","",A13+6) | D13: =IFERROR(INDEX('Operator Master'!$B$5:$B$504,MATCH(C13,'Operator Master'!$A$5:$A$504,0)),"")
B14: =IF(A14="","",A14+6) | D14: =IFERROR(INDEX('Operator Master'!$B$5:$B$504,MATCH(C14,'Operator Master'!$A$5:$A$504,0)),"")
B15: =IF(A15="","",A15+6) | D15: =IFERROR(INDEX('Operator Master'!$B$5:$B$504,MATCH(C15,'Operator Master'!$A$5:$A$504,0)),"")
B16: =IF(A16="","",A16+6) | D16: =IFERROR(INDEX('Operator Master'!$B$5:$B$504,MATCH(C16,'Operator Master'!$A$5:$A$504,0)),"")
... B504: =IF(A504="","",A504+6) | D504: =IFERROR(INDEX('Operator Master'!$B$5:$B$504,MATCH(C504,'Operator Master'!$A$5:$A$504,0)),"")

Sheet Loom Master
A1: STL FU — WEAVING | LOOM MASTER
A2: Permanent loom database. Add or update loom specifications here; routine daily KPI entry is done in Data Entry.
A4: Loom No | B4: Machine Type | C4: RPM Standard | D4: Loom Width | E4: Shift Pattern | F4: Active | G4: Operator Assignment Notes | H4: Remarks
A5: Loom-A 1 | B5: AIRJET | C5: 800 | D5: 190 CM | F5: Yes
A6: Loom-A 2 | B6: AIRJET | C6: 800 | D6: 190 CM | F6: Yes
A7: Loom-A 3 | B7: AIRJET | C7: 800 | D7: 190 CM | F7: Yes
A8: Loom-A 4 | B8: AIRJET | C8: 800 | D8: 190 CM | F8: Yes
A9: Loom-A 5 | B9: AIRJET | C9: 800 | D9: 190 CM | F9: Yes
A10: Loom-A 6 | B10: AIRJET | C10: 800 | D10: 190 CM | F10: Yes
A11: Loom-A 7 | B11: AIRJET | C11: 800 | D11: 190 CM | F11: Yes
A12: Loom-B 1 | B12: AIRJET | C12: 800 | D12: 190 CM | F12: Yes
A13: Loom-B 2 | B13: AIRJET | C13: 800 | D13: 190 CM | F13: Yes
A14: Loom-B 3 | B14: AIRJET | C14: 800 | D14: 190 CM | F14: Yes
A15: Loom-B 4 | B15: AIRJET | C15: 800 | D15: 190 CM | F15: Yes
A16: Loom-B 5 | B16: AIRJET | C16: 800 | D16: 190 CM | F16: Yes
... A104: Loom-O 6 | B104: RAPIER | C104: 600 | D104: 220 CM | F104: Yes
A105: Loom-P 1 | B105: RAPIER | C105: 600 | D105: 220 CM
A106: Loom-P 2 | B106: RAPIER | C106: 600 | D106: 220 CM
A107: Loom-P 3 | B107: RAPIER | C107: 600 | D107: 220 CM
A108: Loom-P 4 | B108: RAPIER | C108: 600 | D108: 220 CM
A109: Loom-P 5 | B109: RAPIER | C109: 600 | D109: 220 CM
A110: Loom-P 6 | B110: RAPIER | C110: 600 | D110: 220 CM
A111: Loom-Q 1 | B111: RAPIER | C111: 600 | D111: 220 CM
A112: Loom-Q 2 | B112: RAPIER | C112: 600 | D112: 220 CM
A113: Loom-Q 3 | B113: RAPIER | C113: 600 | D113: 220 CM
A114: Loom-Q 4 | B114: RAPIER | C114: 600 | D114: 220 CM
A115: Loom-Q 5 | B115: RAPIER | C115: 600 | D115: 220 CM
A116: Loom-Q 6 | B116: RAPIER | C116: 600 | D116: 220 CM
... A144: Loom-V 6 | B144: RAPIER-DOBBY | C144: 600 | D144: 220 CM

Sheet Fault Master
A1: WEAVING | FAULT-WISE MASTER
A2: Controlled fault vocabulary used by the Data Entry form and detailed fault log.
A4: Fault Code | B4: Fault Category | C4: Fault Name | D4: Severity | E4: Operator Responsibility | F4: Target / 1000 yd | G4: Standard Action
A5: WARP-01 | B5: Warp | C5: Warp Break | D5: Medium | E5: Yes | F5: 2 | G5: Check tension/yarn path
A6: WEFT-01 | B6: Weft | C6: Weft Break | D6: Medium | E6: Yes | F6: 3 | G6: Check weft package/tension
A7: WEFT-02 | B7: Weft | C7: Missing Pick | D7: High | E7: Yes | F7: 0.5 | G7: Check detector/timing
A8: FAB-01 | B8: Fabric | C8: Thick Place | D8: Medium | E8: Partial | F8: 0.5 | G8: Check setting/yarn
A9: FAB-02 | B9: Fabric | C9: Thin Place | D9: Medium | E9: Partial | F9: 0.5 | G9: Check setting/yarn
A10: FAB-03 | B10: Fabric | C10: Slub / Foreign Matter | D10: Medium | E10: Partial | F10: 0.5 | G10: Check yarn/handling
A11: FAB-04 | B11: Fabric | C11: Hole / Tear | D11: High | E11: Partial | F11: 0.2 | G11: Check loom/temple/reed
A12: EDGE-01 | B12: Edge | C12: Loose Edge | D12: Medium | E12: Yes | F12: 0.5 | G12: Check temple/tension
A13: MARK-01 | B13: Mark | C13: Starting / Stop Mark | D13: Medium | E13: Yes | F13: 0.5 | G13: Improve restart procedure
A14: MARK-02 | B14: Mark | C14: Reed Mark | D14: High | E14: Partial | F14: 0.2 | G14: Inspect reed/dent
A15: OIL-01 | B15: Stain | C15: Oil / Grease Stain | D15: High | E15: Partial | F15: 0.2 | G15: Check leakage/cleanliness
A16: DENS-01 | B16: Construction | C16: Pick Density Variation | D16: High | E16: Partial | F16: 0.5 | G16: Check speed/take-up
A17: OTHER | B17: Other | C17: Other Fault | D17: Low | E17: Review | F17: 1 | G17: Record root cause

Sheet Legacy Backup
A1: STL FU — WEAVING | EASY DAILY DATA ENTRY
A2: Routine users should work mainly on this sheet. Enter white cells only; blue/gray cells are dropdowns or automatic calculations. Shift is retained as planned vs actual.
A3: KPI ENTRY: one row = one operator + one date + one actual shift. If the actual shift differs from the roster, keep the roster unchanged and select Changed/Temporary + reason here.
A5: Record No | B5: Date | C5: Planned Shift | D5: Actual Shift | E5: Shift Status | F5: Shift Change Reason | G5: Operator ID | H5: Operator Name | I5: Supervisor | J5: No. of Looms | K5: Loom Nos. | L5: AVG RPM | M5: Avg PPI | N5: Production Target (yd) | O5: Production Actual (yd) | P5: Running Hr Target | Q5: Total Running Hr Target | R5: Running Hr Actual | S5: Rejection Yds | T5: Warp Break | U5: Weft Break | V5: Missing Pick | W5: Stop Mark | X5: Start Mark | Y5: L. End | Z5: Y. Mix | AA5: Other Fault | AB5: Housekeeping % | AC5: Attendance / Discipline % | AD5: SOP / Safety % | AE5: Supervisor Remarks | AF5: Operator Comments | AG5: Verified
A6: 1 | B6: 46288 | C6: A | D6: A | E6: Normal | G6: STL005494 | H6: =IFERROR(INDEX('Operator Master'!$B$5:$B$504,MATCH(G6,'Operator Master'!$A$5:$A$504,0)),"") -> MD. MAHABUB ALAM | J6: 8 | K6: O4,O5,O6,P4,P5,Q4,Q5,Q6 | L6: 531.25 | M6: 42 | N6: 1500 | O6: 1130 | P6: 8 | Q6: =P6*J6 -> 64 | R6: 61 | S6: 32 | T6: 3 | U6: 5 | V6: 3 | W6: 5 | X6: 3 | Y6: 0 | Z6: 0 | AB6: 80 | AC6: 100 | AD6: 90 | AG6: ok
A7: 2 | B7: 46288 | C7: B | D7: A | E7: Replace | F7: Manpower shortage | G7: STL005476 | H7: =IFERROR(INDEX('Operator Master'!$B$5:$B$504,MATCH(G7,'Operator Master'!$A$5:$A$504,0)),"") -> MD. RIPU MIAH | J7: 9 | K7: G6,G7,H5,H6,H7,I6,I7,J6,J7 | L7: 569.44444 | M7: 43.11 | N7: 1800 | O7: 1127 | P7: 8 | Q7: =P7*J7 -> 72 | R7: 68 | S7: 17 | T7: 6 | U7: 4 | V7: 7 | W7: 3 | X7: 6 | Y7: 1 | Z7: 0 | AB7: 90 | AC7: 95 | AD7: 100 | AG7: ok
A8: 3 | B8: 46288 | C8: A | D8: A | E8: Normal | G8: STL005492 | H8: =IFERROR(INDEX('Operator Master'!$B$5:$B$504,MATCH(G8,'Operator Master'!$A$5:$A$504,0)),"") -> MD. MINHAZ ALI | J8: 10 | K8: K1,K2,K3,K4,K5,L1,L2,L3,L4,L5 | L8: 537.5 | M8: 41.6 | N8: 1900 | O8: 1602 | P8: 8 | Q8: =P8*J8 -> 80 | R8: 79 | S8: 20 | T8: 4 | U8: 4 | V8: 1 | W8: 3 | X8: 2 | Y8: 0 | Z8: 0 | AB8: 95 | AC8: 100 | AD8: 100 | AG8: ok
A9: 4 | B9: 46288 | C9: A | D9: A | E9: Normal | G9: STL005502 | H9: =IFERROR(INDEX('Operator Master'!$B$5:$B$504,MATCH(G9,'Operator Master'!$A$5:$A$504,0)),"") -> MD. FORIDUL ISLAM | J9: 9 | K9: G1,G2,G3,G4,G5,H1,H2,H3,H4 | L9: 519.44444 | M9: 44.78 | N9: 1500 | O9: 781 | P9: 8 | Q9: =P9*J9 -> 72 | R9: 60 | S9: 16 | T9: 2 | U9: 5 | V9: 3 | W9: 6 | X9: 2 | Y9: 3 | Z9: 0 | AB9: 90 | AC9: 100 | AD9: 100 | AG9: ok
A10: 5 | B10: 46288 | G10: STL005507 | H10: =IFERROR(INDEX('Operator Master'!$B$5:$B$504,MATCH(G10,'Operator Master'!$A$5:$A$504,0)),"") -> MD. SAIFUL ISLAM-2 | J10: 10 | K10: I1,I2,I3,I4,I5,J1,J2,J3,J4,J5 | L10: 582.5 | M10: 43.7 | N10: 1900 | O10: 1170 | P10: 8 | Q10: =P10*J10 -> 80 | R10: 78 | S10: 12 | T10: 5 | U10: 3 | V10: 4 | W10: 1 | X10: 5 | Y10: 1 | Z10: 1 | AB10: 95 | AC10: 100 | AD10: 95 | AG10: ok
A11: 6 | B11: 46288 | G11: STL005510 | H11: =IFERROR(INDEX('Operator Master'!$B$5:$B$504,MATCH(G11,'Operator Master'!$A$5:$A$504,0)),"") -> MD. ZIAUL HAQUE | J11: 9 | K11: R3,R4,R5,R6,S4,S5,T4,T5,T6 | L11: 558.33333 | M11: 41.22 | N11: 1800 | O11: 1598 | P11: 8 | Q11: =P11*J11 -> 72 | R11: 68
A12: 7 | B12: 46288 | G12: STL005466 | H12: =IFERROR(INDEX('Operator Master'!$B$5:$B$504,MATCH(G12,'Operator Master'!$A$5:$A$504,0)),"") -> MD. ANOWAR HOSEN-3 | J12: 9 | K12: U2,U4,U5,U6,V2,V3,V4,V5,V6 | L12: 505.55556 | M12: 44.78 | N12: 1600 | O12: 1156 | P12: 8 | Q12: =P12*J12 -> 72
A13: 8 | B13: 46288 | G13: STL005489 | H13: =IFERROR(INDEX('Operator Master'!$B$5:$B$504,MATCH(G13,'Operator Master'!$A$5:$A$504,0)),"") -> MD. ALAM MIA | J13: 9 | K13: C1,C2,D1,D2,D3,E1,E2,F1,F2 | L13: 555.55556 | M13: =377/9 -> 41.888889 | N13: 1750 | O13: 1255 | P13: 8 | Q13: =P13*J13 -> 72
A14: 9 | B14: 46288 | G14: STL005490 | H14: =IFERROR(INDEX('Operator Master'!$B$5:$B$504,MATCH(G14,'Operator Master'!$A$5:$A$504,0)),"") -> MD. MOMINUL ISLAM | J14: 5 | K14: Q1,Q2,S1,S2,S3 | L14: 545 | M14: 41.8 | N14: 1100 | O14: 876 | P14: 8 | Q14: =P14*J14 -> 40
A15: 10 | B15: 46288 | G15: STL005487 | H15: =IFERROR(INDEX('Operator Master'!$B$5:$B$504,MATCH(G15,'Operator Master'!$A$5:$A$504,0)),"") -> MD. JAHIDUL ISLAM HOWLADER | J15: 9 | K15: C3,C4,C5,C6,C7,D4,D5,D6,D7 | L15: 555.55556 | M15: 43.78 | N15: 1700 | O15: 1187 | P15: 8 | Q15: =P15*J15 -> 72
A16: 11 | B16: 46288 | G16: STL005511 | H16: =IFERROR(INDEX('Operator Master'!$B$5:$B$504,MATCH(G16,'Operator Master'!$A$5:$A$504,0)),"") -> MD. RIPON MIA-2 | J16: 10 | K16: K6,L6,M3,M4,M5,M6,N3,N4,N5,N6 | L16: 530 | M16: 44.7 | N16: 1800 | O16: 1265 | P16: 8 | Q16: =P16*J16 -> 80
A17: 12 | B17: 46288 | G17: STL005516 | H17: =IFERROR(INDEX('Operator Master'!$B$5:$B$504,MATCH(G17,'Operator Master'!$A$5:$A$504,0)),"") -> GOULAM RABBANI | J17: 10 | K17: E3,E4,E5,E6,E7,F3,F4,F5,F6,F7 | L17: 555 | M17: 41.9 | N17: 1700 | O17: 1292 | P17: 8 | Q17: =P17*J17 -> 80
A18: 13 | B18: 46288 | G18: STL005513 | H18: =IFERROR(INDEX('Operator Master'!$B$5:$B$504,MATCH(G18,'Operator Master'!$A$5:$A$504,0)),"") -> MD. HABIBUR RAHMAN | J18: 9 | K18: M1,M2,N1,P1,P2,P3,O1,O2,O3 | L18: 541.66667 | M18: 42.44 | N18: 1700 | O18: 1168 | P18: 8 | Q18: =P18*J18 -> 72
A19: 14 | B19: 46288 | G19: STL005520 | H19: =IFERROR(INDEX('Operator Master'!$B$5:$B$504,MATCH(G19,'Operator Master'!$A$5:$A$504,0)),"") -> MD. SAIFUL ISLAM-3 | J19: 9 | K19: I1,I2,I3,I4,J1,J2,J3,J4,J5 | L19: 525 | M19: 39.22 | N19: 1600 | P19: 8 | Q19: =P19*J19 -> 72
A20: 15 | B20: 46288 | G20: STL005488 | H20: =IFERROR(INDEX('Operator Master'!$B$5:$B$504,MATCH(G20,'Operator Master'!$A$5:$A$504,0)),"") -> MD. JAKIR HOSEN | J20: 10 | K20: K1,K2,K3,K4,K5,L1,L2,L3,L4,L5 | L20: 537.5 | M20: 41.6 | N20: 1800 | P20: 8 | Q20: =P20*J20 -> 80
A21: 16 | B21: 46288 | G21: STL005916 | H21: =IFERROR(INDEX('Operator Master'!$B$5:$B$504,MATCH(G21,'Operator Master'!$A$5:$A$504,0)),"") -> AZIZUL HAQUE | J21: 8 | K21: C1,C2,D1,D2,E1,E2,F1,F2 | L21: 559.375 | M21: 41.75 | N21: 1500 | P21: 8 | Q21: =P21*J21 -> 64
A22: 17 | B22: 46288 | G22: STL007346 | H22: =IFERROR(INDEX('Operator Master'!$B$5:$B$504,MATCH(G22,'Operator Master'!$A$5:$A$504,0)),"") -> MD. ANARUL ISLAM | J22: 8 | K22: S2,S3,S4,S5,T2,T4,T5,T6 | L22: 553.125 | M22: 41.25 | N22: 1600 | P22: 8 | Q22: =P22*J22 -> 64
A23: 18 | B23: 46288 | G23: STL007421 | H23: =IFERROR(INDEX('Operator Master'!$B$5:$B$504,MATCH(G23,'Operator Master'!$A$5:$A$504,0)),"") -> MD. ROSHID | J23: 9 | K23: K6,L6,M3,M4,M5,M6,N3,N5,N6 | L23: 533.33333 | M23: 44.67 | N23: 1600 | P23: 8 | Q23: =P23*J23 -> 72
A24: 19 | B24: 46288 | G24: STL007504 | H24: =IFERROR(INDEX('Operator Master'!$B$5:$B$504,MATCH(G24,'Operator Master'!$A$5:$A$504,0)),"") -> MD. AZIM | J24: 10 | K24: C3,C4,C5,C6,C7,D3,D4,D5,D6,D7 | L24: 552.5 | M24: 43.4 | N24: 1800 | P24: 8 | Q24: =P24*J24 -> 80
A25: 20 | B25: 46288 | G25: STL005458 | H25: =IFERROR(INDEX('Operator Master'!$B$5:$B$504,MATCH(G25,'Operator Master'!$A$5:$A$504,0)),"") -> MD. MOTALEB HOSEN | J25: 10 | K25: G1,G2,G3,G4,G5,H1,H2,H3,H4,H5 | L25: 527.5 | M25: 44.8 | N25: 1600 | P25: 8 | Q25: =P25*J25 -> 80
A26: 21 | B26: 46288 | G26: STL005473 | H26: =IFERROR(INDEX('Operator Master'!$B$5:$B$504,MATCH(G26,'Operator Master'!$A$5:$A$504,0)),"") -> MD. KAWSAR ALI | J26: 10 | K26: E3,E4,E5,E6,E7,F3,F4,F5,F6,F7 | L26: 555 | M26: 41.8 | N26: 1900 | P26: 8 | Q26: =P26*J26 -> 80
A27: 22 | B27: 46288 | G27: STL005474 | H27: =IFERROR(INDEX('Operator Master'!$B$5:$B$504,MATCH(G27,'Operator Master'!$A$5:$A$504,0)),"") -> MD. FARMAN ALI | J27: 9 | K27: G6,G7,H6,H7,I5,I6,I7,J6,J7 | L27: 569.44444 | M27: 42.22 | N27: 1700 | P27: 8 | Q27: =P27*J27 -> 72
A28: 23 | B28: 46288 | G28: STL005478 | H28: =IFERROR(INDEX('Operator Master'!$B$5:$B$504,MATCH(G28,'Operator Master'!$A$5:$A$504,0)),"") -> MD. JULHAS UDDIN | J28: 9 | K28: U2,U3,U5,U6,V2,V3,V4,V5,V6 | L28: 505.55556 | M28: 44.81 | N28: 1500 | P28: 8 | Q28: =P28*J28 -> 72
A29: 24 | B29: 46288 | G29: STL005493 | H29: =IFERROR(INDEX('Operator Master'!$B$5:$B$504,MATCH(G29,'Operator Master'!$A$5:$A$504,0)),"") -> MD. ABDUL AWAL | J29: 7 | K29: Q1,Q2,Q4,R1,R3,R4,S1 | L29: 539.28571 | M29: 40.43 | N29: 1400 | P29: 8 | Q29: =P29*J29 -> 56
A30: 25 | B30: 46288 | G30: STL005469 | H30: =IFERROR(INDEX('Operator Master'!$B$5:$B$504,MATCH(G30,'Operator Master'!$A$5:$A$504,0)),"") -> MD. DULU MIA | J30: 8 | K30: M1,M2,N1,O2,O3,P1,P2,P3 | L30: 540.625 | M30: 42.63 | N30: 1500 | P30: 8 | Q30: =P30*J30 -> 64
A31: 26 | B31: 46288 | G31: STL005464 | H31: =IFERROR(INDEX('Operator Master'!$B$5:$B$504,MATCH(G31,'Operator Master'!$A$5:$A$504,0)),"") -> SREE SUSANTO CHANDRA | J31: 8 | K31: O5,O6,P4,P5,Q5,Q6,R5,R6 | L31: 543.75 | M31: 42.5 | N31: 1500 | P31: 8 | Q31: =P31*J31 -> 64
A32: 27 | B32: 46288 | G32: STL005471 | H32: =IFERROR(INDEX('Operator Master'!$B$5:$B$504,MATCH(G32,'Operator Master'!$A$5:$A$504,0)),"") -> MD. ASHRAFUL ISLAM | L32: 545 | M32: 41.8 | P32: 8 | Q32: =P32*J32 -> 0
A33: 28 | B33: 46288 | G33: STL005525 | H33: =IFERROR(INDEX('Operator Master'!$B$5:$B$504,MATCH(G33,'Operator Master'!$A$5:$A$504,0)),"") -> MD. ASRAF AKANDA | L33: 555.55556 | M33: 43.78 | P33: 8 | Q33: =P33*J33 -> 0
A34: 29 | B34: 46288 | G34: STL005503 | H34: =IFERROR(INDEX('Operator Master'!$B$5:$B$504,MATCH(G34,'Operator Master'!$A$5:$A$504,0)),"") -> MD. JIHADUZZAMAN (JIAD) | L34: 530 | M34: 44.7 | P34: 8 | Q34: =P34*J34 -> 0
A35: 30 | B35: 46288 | G35: STL005519 | H35: =IFERROR(INDEX('Operator Master'!$B$5:$B$504,MATCH(G35,'Operator Master'!$A$5:$A$504,0)),"") -> MD. MOZNU SHEKH | L35: 555 | M35: 41.9 | P35: 8 | Q35: =P35*J35 -> 0
A36: 31 | B36: 46288 | G36: STL005500 | H36: =IFERROR(INDEX('Operator Master'!$B$5:$B$504,MATCH(G36,'Operator Master'!$A$5:$A$504,0)),"") -> MD. AMINUR ISLAM | L36: 541.66667 | M36: 42.44 | P36: 8 | Q36: =P36*J36 -> 0
A37: 32 | B37: 46288 | G37: STL006681 | H37: =IFERROR(INDEX('Operator Master'!$B$5:$B$504,MATCH(G37,'Operator Master'!$A$5:$A$504,0)),"") -> MD. BABUL MIAH | L37: 525 | M37: 39.22 | P37: 8 | Q37: =P37*J37 -> 0
A38: 33 | B38: 46288 | G38: STL006736 | H38: =IFERROR(INDEX('Operator Master'!$B$5:$B$504,MATCH(G38,'Operator Master'!$A$5:$A$504,0)),"") -> MD. ROFIKUL ISLAM | L38: 537.5 | M38: 41.6 | P38: 8 | Q38: =P38*J38 -> 0
A39: 34 | B39: 46288 | G39: STL007340 | H39: =IFERROR(INDEX('Operator Master'!$B$5:$B$504,MATCH(G39,'Operator Master'!$A$5:$A$504,0)),"") -> MD. AMINUL ISLAM-2 | L39: 559.375 | M39: 41.75 | P39: 8 | Q39: =P39*J39 -> 0
A40: 35 | B40: 46288 | G40: STL007341 | H40: =IFERROR(INDEX('Operator Master'!$B$5:$B$504,MATCH(G40,'Operator Master'!$A$5:$A$504,0)),"") -> MD. JONY ALOM | L40: 553.125 | M40: 41.25 | P40: 8 | Q40: =P40*J40 -> 0
A41: 36 | B41: 46288 | G41: STL007502 | H41: =IFERROR(INDEX('Operator Master'!$B$5:$B$504,MATCH(G41,'Operator Master'!$A$5:$A$504,0)),"") -> MD. HELIM ISLAM | L41: 533.33333 | M41: 44.67 | P41: 8 | Q41: =P41*J41 -> 0
...

Sheet Standards & Scoring
A1: DENIM MILL — WEAVING | KPI STANDARDS & SCORING
A3: Management control sheet. Change approved targets/weights here. Daily users should not modify this sheet.
A4: KPI Component | B4: Source Metric | C4: Direction | D4: Weight % | E4: Target / Standard | F4: Scoring Note | H4: Grade | I4: Minimum KPI | J4: Incentive
A5: Production | B5: Production Achievement % | C5: Higher | D5: 20 | E5: 100 | F5: Actual loom production ÷ approved loom/style target | H5: A+ | I5: 105 | J5: 1800
A6: Loom Efficiency | B6: Technical Loom Efficiency % | C6: Higher | D6: 15 | E6: 85 | F6: Use approved mill efficiency formula; target is a practical starting standard | H6: A | I6: 100 | J6: 1600
A7: Running / Availability | B7: Loom Availability % | C7: Higher | D7: 15 | E7: 95 | F7: Available loom time after valid downtime | H7: B+ | I7: 95 | J7: 1400
A8: Quality / Rejection | B8: Rejection % | C8: Lower | D8: 15 | E8: 1 | F8: Target 1.00% as a practical denim-mill starting point; replace with mill historical standard | H8: B | I8: 90 | J8: 1200
A9: Fault Control | B9: Faults / 1000 yd | C9: Lower | D9: 10 | E9: 10 | F9: Starting benchmark; set by loom/style family after baseline study | H9: C | I9: 0 | J9: 0
A10: Downtime Control | B10: Downtime Min / 1000 yd | C10: Lower | D10: 10 | E10: 20 | F10: Starting benchmark; excludes planned changeover/approved stoppage
A11: Housekeeping / SOP | B11: Average Housekeeping + SOP/Safety % | C11: Higher | D11: 5 | E11: 95 | F11: Checklist-based assessment
A12: Attendance / Discipline | B12: Attendance / Discipline % | C12: Higher | D12: 5 | E12: 100 | F12: HR/biometric attendance and approved discipline rating
A13: Skill / Process Compliance | B13: Parameter / Process Compliance % | C13: Higher | D13: 5 | E13: 95 | F13: Correct RPM/PPI/setting, procedure adherence and response to abnormalities
A15: Weight total | D15: =SUM(D5:D13) -> 100
A17: STANDARD DENIM MILL CULTURE | B17: Use approved mill/style/loom-family standards wherever available. The targets above are starting control limits, not universal industry laws. Review monthly using 3–6 months of actual data and revise through management approval.
A19: Denim-mill KPI principle | B19: Reward balanced performance: output must not be achieved by sacrificing quality, excessive faults, downtime, SOP or safety. Production is counted once; the other weights measure process stability and operator control.
A21: Target governance | B21: Production target: loom/style/construction based. Efficiency: use mill-approved formula. Rejection, faults and downtime: establish baselines by loom/style family. Attendance: HR/biometric source. Housekeeping/SOP: checklist audit.

Sheet Weaving KPI Data
A1: STL FU — WEAVING | KPI DATABASE & CALCULATIONS
A3: Backend calculation sheet. Do not type here during routine operation.
A4: Record No | B4: Date | C4: Planned Shift | D4: Actual Shift | E4: Shift Status | F4: Shift Change Reason | G4: Operator ID | H4: Operator Name | I4: Supervisor | J4: No. of Looms | K4: Loom No(s) | L4: Avg RPM | M4: Avg PPI | N4: Production Target | O4: Production Actual | P4: Production Achievement % | Q4: Running Hr Target / Loom | R4: Total Loom-Hr Target | S4: Running Hr Actual | T4: Running Achievement % | U4: Loom Efficiency % | V4: Rejection Yds | W4: Rejection % | X4: Warp Break | Y4: Weft Break | Z4: Missing Pick | AA4: Stop Mark | AB4: Start Mark | AC4: L. End | AD4: Y. Mix | AE4: Other Fault | AF4: Fault Total | AG4: Faults / 1000 yd | AH4: Housekeeping % | AI4: Attendance / Discipline % | AJ4: SOP / Safety % | AK4: Supervisor Remarks | AL4: Operator Comments | AM4: Verified | AN4: Production Score | AO4: Efficiency Score | AP4: Running / Availability Score | AQ4: Quality Score | AR4: Fault Score | AS4: Downtime Score | AT4: Housekeeping / SOP Score | AU4: Attendance Score | AV4: Skill / Process Score | AW4: Individual KPI Score | AX4: Grade | AY4: Incentive | AZ4: Theoretical Production yd
A5: ='Daily KPI Entry'!A6 -> 1 | B5: ='Daily KPI Entry'!B6 -> 46288 | C5: ='Daily KPI Entry'!C6 -> A | D5: ='Daily KPI Entry'!D6 -> A | E5: ='Daily KPI Entry'!E6 -> Normal | F5: ='Daily KPI Entry'!F6 -> 0 | G5: ='Daily KPI Entry'!G6 -> STL005494 | H5: ='Daily KPI Entry'!H6 -> MD. MAHABUB ALAM | ... O5: ='Daily KPI Entry'!O6 -> 1130 | P5: =IF(OR(N5="",O5=""),"",IFERROR(O5/N5*100,0)) -> 75.333333 | Q5: ='Daily KPI Entry'!Q6 -> 8 | R5: =IF(J5="","",Q5*J5) -> 64 | S5: ='Daily KPI Entry'!S6 -> 61 | T5: =IF(OR(R5="",S5=""),"",IFERROR(S5/R5*100,0)) -> 95.3125 | U5: =IF(OR(O5="",L5="",M5="",S5="",M5=0),"",IFERROR(O5/(L5*60*S5/(M5*36))*100,0)) -> 87.871938 | V5: ='Daily KPI Entry'!V6 -> 32 | W5: =IF(O5="","",IFERROR(V5/O5*100,0)) -> 2.8318584 | X5: ='Daily KPI Entry'!X6 -> 3 | Y5: ='Daily KPI Entry'!Y6 -> 5 | Z5: ='Daily KPI Entry'!Z6 -> 3 | AA5: ='Daily KPI Entry'!AA6 -> 5 | AB5: ='Daily KPI Entry'!AB6 -> 3 | AC5: ='Daily KPI Entry'!AC6 -> 0 | AD5: ='Daily KPI Entry'!AD6 -> 0 | AE5: ='Daily KPI Entry'!AE6 -> 0 | AF5: =IF(O5="","",SUM(X5:AE5)) -> 19 | AG5: =IF(O5="","",IFERROR(AF5/O5*1000,0)) -> 16.814159 | AH5: ='Daily KPI Entry'!AH6 -> 80 | AI5: ='Daily KPI Entry'!AI6 -> 100 | AJ5: ='Daily KPI Entry'!AJ6 -> 90 | AK5: ='Daily KPI Entry'!AK6 -> 0 | AL5: ='Daily KPI Entry'!AL6 -> 0 | AM5: ='Daily KPI Entry'!AM6 -> 0 | AN5: =IF(P5="","",MIN(120,P5)) -> 75.333333 | AO5: =IF(U5="","",MIN(120,U5)) -> 87.871938 | AP5: =IF(R5="","",MIN(120,IFERROR(S5/R5*100,0))) -> 95.3125 | AQ5: =IF(W5="","",MIN(120,IF(W5=0,120,100*(INDEX('Standards & Scoring'!$E$5:$E$13,MATCH("Quality / Rejection",'Standards & Scoring'!$A$5:$A$13,0))/W5)))) -> 35.3125 | AR5: =IF(AG5="","",MIN(120,IF(AG5=0,120,100*(INDEX('Standards & Scoring'!$E$5:$E$13,MATCH("Fault Control",'Standards & Scoring'!$A$5:$A$13,0))/AG5)))) -> 59.473684 | AS5: =IF(O5="","",MIN(120,IF(SUMIFS('Fault & Downtime Entry'!$L$6:$L$1005,'Fault & Downtime Entry'!$E$6:$E$1005,G5,'Fault & Downtime Entry'!$B$6:$B$1005,B5)=0,120,100*(INDEX('Standards & Scoring'!$E$5:$E$13,MATCH("Downtime Control",'Standards & Scoring'!$A$5:$A$13,0))/IFERROR(SUMIFS('Fault & Downtime Entry'!$L$6:$L$1005,'Fault & Downtime Entry'!$E$6:$E$1005,G5,'Fault & Downtime Entry'!$B$6:$B$1005,B5)/O5*1000,999999))))) -> 120 | AT5: =IF(COUNTA(AH5,AJ5)=0,"",MIN(120,IF(AND(AH5<>"",AJ5<>""),AVERAGE(AH5,AJ5),IF(AH5<>"",AH5,AJ5)))) -> 85 | AU5: =IF(AI5="","",MIN(120,AI5)) -> 100 | AV5: =IF(AJ5="","",MIN(120,AJ5)) -> 90 | AW5: =IF(COUNT(AN5:AV5)<9,"",(AN5*'Standards & Scoring'!$D$5+AO5*'Standards & Scoring'!$D$6+AP5*'Standards & Scoring'!$D$7+AQ5*'Standards & Scoring'!$D$8+AR5*'Standards & Scoring'!$D$9+AS5*'Standards & Scoring'!$D$10+AT5*'Standards & Scoring'!$D$11+AU5*'Standards & Scoring'!$D$12+AV5*'Standards & Scoring'!$D$13)/10000) -> 0.79538576 | AX5: =IF(AW5="","",IF(AW5>=1.05,"A+",IF(AW5>=1,"A",IF(AW5>=0.95,"B+",IF(AW5>=0.9,"B","C"))))) -> C | AY5: =IF(AX5="","",IF(AX5="A+",1800,IF(AX5="A",1600,IF(AX5="B+",1400,IF(AX5="B",1200,0))))) -> 0 | AZ5: =IF(OR(L5="",M5="",S5="",M5=0),"",IFERROR(L5*60*S5/(M5*36),0)) -> 1285.9623
A6: ='Daily KPI Entry'!A7 -> 2 | B6: ='Daily KPI Entry'!B7 -> 46288 | C6: ='Daily KPI Entry'!C7 -> B | D6: ='Daily KPI Entry'!D7 -> A | E6: ='Daily KPI Entry'!E7 -> Replace | F6: ='Daily KPI Entry'!F7 -> Manpower shortage | G6: ='Daily KPI Entry'!G7 -> STL005476 | H6: ='Daily KPI Entry'!H7 -> MD. RIPU MIAH | ... O6: ='Daily KPI Entry'!O7 -> 1127 | P6: =IF(OR(N6="",O6=""),"",IFERROR(O6/N6*100,0)) -> 62.611111 | Q6: ='Daily KPI Entry'!Q7 -> 8 | R6: =IF(J6="","",Q6*J6) -> 72 | S6: ='Daily KPI Entry'!S7 -> 68 | T6: =IF(OR(R6="",S6=""),"",IFERROR(S6/R6*100,0)) -> 94.444444 | U6: =IF(OR(O6="",L6="",M6="",S6="",M6=0),"",IFERROR(O6/(L6*60*S6/(M6*36))*100,0)) -> 75.282306 | V6: ='Daily KPI Entry'!V7 -> 17 | W6: =IF(O6="","",IFERROR(V6/O6*100,0)) -> 1.5084295 | X6: ='Daily KPI Entry'!X7 -> 6 | Y6: ='Daily KPI Entry'!Y7 -> 4 | Z6: ='Daily KPI Entry'!Z7 -> 7 | AA6: ='Daily KPI Entry'!AA7 -> 3 | AB6: ='Daily KPI Entry'!AB7 -> 6 | AC6: ='Daily KPI Entry'!AC7 -> 1 | AD6: ='Daily KPI Entry'!AD7 -> 0 | AE6: ='Daily KPI Entry'!AE7 -> 0 | AF6: =IF(O6="","",SUM(X6:AE6)) -> 27 | AG6: =IF(O6="","",IFERROR(AF6/O6*1000,0)) -> 23.957409 | AH6: ='Daily KPI Entry'!AH7 -> 90 | AI6: ='Daily KPI Entry'!AI7 -> 95 | AJ6: ='Daily KPI Entry'!AJ7 -> 100 | AK6: ='Daily KPI Entry'!AK7 -> 0 | AL6: ='Daily KPI Entry'!AL7 -> 0 | AM6: ='Daily KPI Entry'!AM7 -> 0 | AN6: =IF(P6="","",MIN(120,P6)) -> 62.611111 | AO6: =IF(U6="","",MIN(120,U6)) -> 75.282306 | AP6: =IF(R6="","",MIN(120,IFERROR(S6/R6*100,0))) -> 94.444444 | AQ6: =IF(W6="","",MIN(120,IF(W6=0,120,100*(INDEX('Standards & Scoring'!$E$5:$E$13,MATCH("Quality / Rejection",'Standards & Scoring'!$A$5:$A$13,0))/W6)))) -> 66.294118 | AR6: =IF(AG6="","",MIN(120,IF(AG6=0,120,100*(INDEX('Standards & Scoring'!$E$5:$E$13,MATCH("Fault Control",'Standards & Scoring'!$A$5:$A$13,0))/AG6)))) -> 41.740741 | AS6: =IF(O6="","",MIN(120,IF(SUMIFS('Fault & Downtime Entry'!$L$6:$L$1005,'Fault & Downtime Entry'!$E$6:$E$1005,G6,'Fault & Downtime Entry'!$B$6:$B$1005,B6)=0,120,100*(INDEX('Standards & Scoring'!$E$5:$E$13,MATCH("Downtime Control",'Standards & Scoring'!$A$5:$A$13,0))/IFERROR(SUMIFS('Fault & Downtime Entry'!$L$6:$L$1005,'Fault & Downtime Entry'!$E$6:$E$1005,G6,'Fault & Downtime Entry'!$B$6:$B$1005,B6)/O6*1000,999999))))) -> 120 | AT6: =IF(COUNTA(AH6,AJ6)=0,"",MIN(120,IF(AND(AH6<>"",AJ6<>""),AVERAGE(AH6,AJ6),IF(AH6<>"",AH6,AJ6)))) -> 95 | AU6: =IF(AI6="","",MIN(120,AI6)) -> 95 | AV6: =IF(AJ6="","",MIN(120,AJ6)) -> 100 | AW6: =IF(COUNT(AN6:AV6)<9,"",(AN6*'Standards & Scoring'!$D$5+AO6*'Standards & Scoring'!$D$6+AP6*'Standards & Scoring'!$D$7+AQ6*'Standards & Scoring'!$D$8+AR6*'Standards & Scoring'!$D$9+AS6*'Standards & Scoring'!$D$10+AT6*'Standards & Scoring'!$D$11+AU6*'Standards & Scoring'!$D$12+AV6*'Standards & Scoring'!$D$13)/10000) -> 0.78599427 | AX6: =IF(AW6="","",IF(AW6>=1.05,"A+",IF(AW6>=1,"A",IF(AW6>=0.95,"B+",IF(AW6>=0.9,"B","C"))))) -> C | AY6: =IF(AX6="","",IF(AX6="A+",1800,IF(AX6="A",1600,IF(AX6="B+",1400,IF(AX6="B",1200,0))))) -> 0 | AZ6: =IF(OR(L6="",M6="",S6="",M6=0),"",IFERROR(L6*60*S6/(M6*36),0)) -> 1497.0317
